Workbook
Name Dynamic_Filter: OFFSET('PT ABC'!#REF!,,,COUNTIF('PT ABC'!#REF!,"?*"),)
Name validation_list: OFFSET('PT ABC'!#REF!,,,COUNTIF('PT ABC'!#REF!,"?*"))

Sheet Article Master
A1: S No. | B1: Details | C1: PARTICULAR | D1: Article | E1: GST % | F1: Rate | G1: Remarks | H1: Changes | K1: Input Field
A2: 1 | B2: Acrylic | C2: 3MM CLEAR ACRYLIC WITH LASER CUT | D2: 720001565 | E2: 0.18 | F2: 133
A3: =A2+1 -> 2 | B3: Acrylic | C3: 5mm Acrylic Sheet with Laser cutting | D3: 720001384 | E3: 0.18 | F3: 210
A4: =A3+1 -> 3 | B4: Acrylic | C4: Acrylic Brand Plate 1200mm X 400mm | D4: 720001181 | E4: 0.18 | F4: #N/A
A5: =A4+1 -> 4 | B5: Acrylic | C5: Acrylic Brand Plate 450mmX150MM | D5: 720001184 | E5: 0.18 | F5: #N/A
A6: =A5+1 -> 5 | B6: Acrylic | C6: Acrylic Brand Plate 750mm X 250mm | D6: 720001183 | E6: 0.18 | F6: #N/A
A7: =A6+1 -> 6 | B7: Acrylic | C7: Acrylic Brand Plate 900mm X 300mm | D7: 720001182 | E7: 0.18 | F7: #N/A
A8: =A7+1 -> 7 | B8: Adhesive | C8: Acrabond 20ml | D8: 720000030 | E8: 0.18 | F8: 40
A9: =A8+1 -> 8 | B9: Canvas | C9: Eco Solvent Print On Canvas | D9: 720001988 | E9: 0.18 | F9: 110
A10: =A9+1 -> 9 | B10: Latex | C10: Latex Print on Canvas | D10: 720002026 | E10: 0.18 | F10: 120
A11: =A10+1 -> 10 | B11: Canvas | C11: UV Print On Canvas | D11: 720002145 | E11: 0.18 | F11: 135
A12: =A11+1 -> 11 | B12: Carpet | C12: Floor Carpet | D12: 720001737 | E12: 0.12 | F12: 20
A13: =A12+1 -> 12 | B13: Vinyl | C13: Clear Vinyl Printing | D13: 720001772 | E13: 0.18 | F13: 25
A14: =A13+1 -> 13 | B14: Fabric | C14: FABRIC PRINT WITH SILICON TAPE & STITCHI | D14: 720002255 | E14: 0.18 | F14: 90
A15: =A14+1 -> 14 | B15: Flex | C15: Star Flex Eco solvent Print | D15: 720002045 | E15: 0.18 | F15: 25
A16: =A15+1 -> 15 | B16: Flex | C16: Plain Flex | D16: 720002025 | E16: 0.18 | F16: 7
A17: =A16+1 -> 16 | B17: Flex | C17: Backlit Flex Printing | D17: 720002011 | E17: 0.18 | F17: 30
A18: =A17+1 -> 17 | B18: Flex | C18: BACKLIT FLEX PRINT-16 OZ | D18: 720001775 | E18: 0.18 | F18: 25
A19: =A18+1 -> 18 | B19: Flex | C19: Frontlit Flex Printing | D19: 720002010 | E19: 0.18 | F19: 12
A20: =A19+1 -> 19 | B20: Flex | C20: Frontlit Flex Print On Branded Media | D20: 720001761 | E20: 0.18 | F20: 16
A21: =A20+1 -> 20 | B21: Flex | C21: PVC Flex | D21: 720002206 | E21: 0.18 | F21: #N/A
A22: =A21+1 -> 21 | B22: Vinyl | C22: Frosted Vinyl Cutting | D22: 720001980 | E22: 0.18 | F22: #N/A
A23: =A22+1 -> 22 | B23: Vinyl | C23: 3M Frosted Vinyl | D23: 720001345 | E23: 0.18 | F23: #N/A
A24: =A23+1 -> 23 | B24: Vinyl | C24: Lamination | D24: 720002012 | E24: 0.18 | F24: 8
A25: =A24+1 -> 24 | B25: Light/Festive | C25: TUBELIGHT,CHOWK & WIRING | D25: 720001392 | E25: 0.18 | F25: #N/A
A26: =A25+1 -> 25 | B26: Acrylic | C26: LIT Brand Plate with Vinyl | D26: 720002355 | E26: 0.18 | F26: #N/A
A27: =A26+1 -> 26 | B27: Acrylic | C27: LIT Brand Plate with Duco Paint | D27: 720002356 | E27: 0.18 | F27: #N/A
A28: =A27+1 -> 27 | B28: Metal | C28: J Hook | D28: 720001435 | E28: 0.18 | F28: #N/A
A29: =A28+1 -> 28 | B29: Metal | C29: S Hook | D29: 720001407 | E29: 0.18 | F29: #N/A
A30: =A29+1 -> 29 | B30: Digital | C30: A3 - Danglers - Digital | D30: 720002033 | E30: 0.18 | F30: NA
A31: =A30+1 -> 30 | B31: Digital | C31: A3 - Signage - Digital | D31: 720000064 | E31: 0.18 | F31: 18
A32: =A31+1 -> 31 | B32: Digital | C32: A4 - Signage - Digital | D32: 720000062 | E32: 0.18 | F32: 9
A33: =A32+1 -> 32 | B33: Digital | C33: A5 - Signage - Digital | D33: 720000063 | E33: 0.18 | F33: 6
A34: =A33+1 -> 33 | B34: Digital | C34: Shelf Talker 6" X 8" - Digital | D34: 720002024 | E34: 0.18 | F34: NA
A35: =A34+1 -> 34 | B35: Digital | C35: Wobbler Printing - Digital | D35: 720002016 | E35: 0.18 | F35: #N/A
A36: =A35+1 -> 35 | B36: Digital | C36: A2 - SIGNAGE - DIGITAL 300GSM | D36: 720001935 | E36: 0.18 | F36: #N/A
A37: =A36+1 -> 36 | B37: Offset | C37: A3 - Danglers - Offset | D37: 720002032 | E37: 0.18 | F37: #N/A
A38: =A37+1 -> 37 | B38: Offset | C38: A4 - Signage - Offset | D38: 720000057 | E38: 0.18 | F38: NA
A39: =A38+1 -> 38 | B39: Offset | C39: A5 - Signage - Offset | D39: 720000059 | E39: 0.18 | F39: NA
A40: =A39+1 -> 39 | B40: Offset | C40: Shelf Talker 2" X 5.5" - Offset | D40: 720001805 | E40: 0.18 | F40: NA
...

Sheet Sheet1
B3: Unique Drop Down | C3: Dependent Drop Down
B4: Light/Festive | F4: =OFFSET($C$10,MATCH($B$4,$B$11:$B$37,0),,,COUNTIF(OFFSET($C$10,MATCH($B$4,$B$11:$B$37,0),,1,40),"?*")) -> Aluminium Profile Fabric LIT Box
M9: ='Article Master'!C6 -> Acrylic Brand Plate 750mm X 250mm
A10: Count | B10: Details
A11: =COUNTIF(Table1[Details],B11) -> 13 | B11: =IFERROR(INDEX(Table1[Details],MATCH(0,INDEX(COUNTIF($B$10:B10,Table1[Details]),),0)),"") -> Acrylic | C11: =IF(COLUMNS($C$10:C10)<=$A11,INDEX(Table1[[PARTICULAR]:[PARTICULAR]],_xlfn.AGGREGATE(15,3,(Table1[[#This Row],[Details]:[Details]]=$B11)/(Table1[[#This Row],[Details]:[Details]]=$B11)*(ROW(Table1[[Details]:[Details]])-ROW(Table1[[#Headers],[Details]])),COLUMNS($C$10:C10))),"") -> 3MM CLEAR ACRYLIC WITH LASER CUT | D11: =IF(COLUMNS($C$10:D10)<=$A11,INDEX(Table1[[PARTICULAR]:[PARTICULAR]],_xlfn.AGGREGATE(15,3,(Table1[[#This Row],[Details]:[Details]]=$B11)/(Table1[[#This Row],[Details]:[Details]]=$B11)*(ROW(Table1[[Details]:[Details]])-ROW(Table1[[#Headers],[Details]])),COLUMNS($C$10:D10))),"") -> 5mm Acrylic Sheet with Laser cutting | E11: =IF(COLUMNS($C$10:E10)<=$A11,INDEX(Table1[[PARTICULAR]:[PARTICULAR]],_xlfn.AGGREGATE(15,3,(Table1[[#This Row],[Details]:[Details]]=$B11)/(Table1[[#This Row],[Details]:[Details]]=$B11)*(ROW(Table1[[Details]:[Details]])-ROW(Table1[[#Headers],[Details]])),COLUMNS($C$10:E10))),"") -> Acrylic Brand Plate 1200mm X 400mm | F11: =IF(COLUMNS($C$10:F10)<=$A11,INDEX(Table1[[PARTICULAR]:[PARTICULAR]],_xlfn.AGGREGATE(15,3,(Table1[[#This Row],[Details]:[Details]]=$B11)/(Table1[[#This Row],[Details]:[Details]]=$B11)*(ROW(Table1[[Details]:[Details]])-ROW(Table1[[#Headers],[Details]])),COLUMNS($C$10:F10))),"") -> Acrylic Brand Plate 450mmX150MM | G11: =IF(COLUMNS($C$10:G10)<=$A11,INDEX(Table1[[PARTICULAR]:[PARTICULAR]],_xlfn.AGGREGATE(15,3,(Table1[[#This Row],[Details]:[Details]]=$B11)/(Table1[[#This Row],[Details]:[Details]]=$B11)*(ROW(Table1[[Details]:[Details]])-ROW(Table1[[#Headers],[Details]])),COLUMNS($C$10:G10))),"") -> Acrylic Brand Plate 750mm X 250mm | H11: =IF(COLUMNS($C$10:H10)<=$A11,INDEX(Table1[[PARTICULAR]:[PARTICULAR]],_xlfn.AGGREGATE(15,3,(Table1[[#This Row],[Details]:[Details]]=$B11)/(Table1[[#This Row],[Details]:[Details]]=$B11)*(ROW(Table1[[Details]:[Details]])-ROW(Table1[[#Headers],[Details]])),COLUMNS($C$10:H10))),"") -> Acrylic Brand Plate 900mm X 300mm | I11: =IF(COLUMNS($C$10:I10)<=$A11,INDEX(Table1[[PARTICULAR]:[PARTICULAR]],_xlfn.AGGREGATE(15,3,(Table1[[#This Row],[Details]:[Details]]=$B11)/(Table1[[#This Row],[Details]:[Details]]=$B11)*(ROW(Table1[[Details]:[Details]])-ROW(Table1[[#Headers],[Details]])),COLUMNS($C$10:I10))),"") -> LIT Brand Plate with Vinyl | J11: =IF(COLUMNS($C$10:J10)<=$A11,INDEX(Table1[[PARTICULAR]:[PARTICULAR]],_xlfn.AGGREGATE(15,3,(Table1[[#This Row],[Details]:[Details]]=$B11)/(Table1[[#This Row],[Details]:[Details]]=$B11)*(ROW(Table1[[Details]:[Details]])-ROW(Table1[[#Headers],[Details]])),COLUMNS($C$10:J10))),"") -> LIT Brand Plate with Duco Paint | ... CB11: =IF(COLUMNS($C$10:CB10)<=$A11,INDEX(Table1[[PARTICULAR]:[PARTICULAR]],_xlfn.AGGREGATE(15,3,(Table1[[#This Row],[Details]:[Details]]=$B11)/(Table1[[#This Row],[Details]:[Details]]=$B11)*(ROW(Table1[[Details]:[Details]])-ROW(Table1[[#Headers],[Details]])),COLUMNS($C$10:CB10))),"")
A12: =COUNTIF(Table1[Details],B12) -> 2 | B12: =IFERROR(INDEX(Table1[Details],MATCH(0,INDEX(COUNTIF($B$10:B11,Table1[Details]),),0)),"") -> Adhesive | C12: =IF(COLUMNS($C$10:C11)<=$A12,INDEX(Table1[[PARTICULAR]:[PARTICULAR]],_xlfn.AGGREGATE(15,3,(Table1[[#This Row],[Details]:[Details]]=$B12)/(Table1[[#This Row],[Details]:[Details]]=$B12)*(ROW(Table1[[Details]:[Details]])-ROW(Table1[[#Headers],[Details]])),COLUMNS($C$10:C11))),"") -> Acrabond 20ml | D12: =IF(COLUMNS($C$10:D11)<=$A12,INDEX(Table1[[PARTICULAR]:[PARTICULAR]],_xlfn.AGGREGATE(15,3,(Table1[[#This Row],[Details]:[Details]]=$B12)/(Table1[[#This Row],[Details]:[Details]]=$B12)*(ROW(Table1[[Details]:[Details]])-ROW(Table1[[#Headers],[Details]])),COLUMNS($C$10:D11))),"") -> Adhesive Coated Tape | E12: =IF(COLUMNS($C$10:E11)<=$A12,INDEX(Table1[[PARTICULAR]:[PARTICULAR]],_xlfn.AGGREGATE(15,3,(Table1[[#This Row],[Details]:[Details]]=$B12)/(Table1[[#This Row],[Details]:[Details]]=$B12)*(ROW(Table1[[Details]:[Details]])-ROW(Table1[[#Headers],[Details]])),COLUMNS($C$10:E11))),"") | F12: =IF(COLUMNS($C$10:F11)<=$A12,INDEX(Table1[[PARTICULAR]:[PARTICULAR]],_xlfn.AGGREGATE(15,3,(Table1[[#This Row],[Details]:[Details]]=$B12)/(Table1[[#This Row],[Details]:[Details]]=$B12)*(ROW(Table1[[Details]:[Details]])-ROW(Table1[[#Headers],[Details]])),COLUMNS($C$10:F11))),"") | G12: =IF(COLUMNS($C$10:G11)<=$A12,INDEX(Table1[[PARTICULAR]:[PARTICULAR]],_xlfn.AGGREGATE(15,3,(Table1[[#This Row],[Details]:[Details]]=$B12)/(Table1[[#This Row],[Details]:[Details]]=$B12)*(ROW(Table1[[Details]:[Details]])-ROW(Table1[[#Headers],[Details]])),COLUMNS($C$10:G11))),"") | H12: =IF(COLUMNS($C$10:H11)<=$A12,INDEX(Table1[[PARTICULAR]:[PARTICULAR]],_xlfn.AGGREGATE(15,3,(Table1[[#This Row],[Details]:[Details]]=$B12)/(Table1[[#This Row],[Details]:[Details]]=$B12)*(ROW(Table1[[Details]:[Details]])-ROW(Table1[[#Headers],[Details]])),COLUMNS($C$10:H11))),"") | I12: =IF(COLUMNS($C$10:I11)<=$A12,INDEX(Table1[[PARTICULAR]:[PARTICULAR]],_xlfn.AGGREGATE(15,3,(Table1[[#This Row],[Details]:[Details]]=$B12)/(Table1[[#This Row],[Details]:[Details]]=$B12)*(ROW(Table1[[Details]:[Details]])-ROW(Table1[[#Headers],[Details]])),COLUMNS($C$10:I11))),"") | J12: =IF(COLUMNS($C$10:J11)<=$A12,INDEX(Table1[[PARTICULAR]:[PARTICULAR]],_xlfn.AGGREGATE(15,3,(Table1[[#This Row],[Details]:[Details]]=$B12)/(Table1[[#This Row],[Details]:[Details]]=$B12)*(ROW(Table1[[Details]:[Details]])-ROW(Table1[[#Headers],[Details]])),COLUMNS($C$10:J11))),"") | ... CB12: =IF(COLUMNS($C$10:CB11)<=$A12,INDEX(Table1[[PARTICULAR]:[PARTICULAR]],_xlfn.AGGREGATE(15,3,(Table1[[#This Row],[Details]:[Details]]=$B12)/(Table1[[#This Row],[Details]:[Details]]=$B12)*(ROW(Table1[[Details]:[Details]])-ROW(Table1[[#Headers],[Details]])),COLUMNS($C$10:CB11))),"")
A13: =COUNTIF(Table1[Details],B13) -> 2 | B13: =IFERROR(INDEX(Table1[Details],MATCH(0,INDEX(COUNTIF($B$10:B12,Table1[Details]),),0)),"") -> Canvas | C13: =IF(COLUMNS($C$10:C12)<=$A13,INDEX(Table1[[PARTICULAR]:[PARTICULAR]],_xlfn.AGGREGATE(15,3,(Table1[[#This Row],[Details]:[Details]]=$B13)/(Table1[[#This Row],[Details]:[Details]]=$B13)*(ROW(Table1[[Details]:[Details]])-ROW(Table1[[#Headers],[Details]])),COLUMNS($C$10:C12))),"") -> Eco Solvent Print On Canvas | D13: =IF(COLUMNS($C$10:D12)<=$A13,INDEX(Table1[[PARTICULAR]:[PARTICULAR]],_xlfn.AGGREGATE(15,3,(Table1[[#This Row],[Details]:[Details]]=$B13)/(Table1[[#This Row],[Details]:[Details]]=$B13)*(ROW(Table1[[Details]:[Details]])-ROW(Table1[[#Headers],[Details]])),COLUMNS($C$10:D12))),"") -> UV Print On Canvas | E13: =IF(COLUMNS($C$10:E12)<=$A13,INDEX(Table1[[PARTICULAR]:[PARTICULAR]],_xlfn.AGGREGATE(15,3,(Table1[[#This Row],[Details]:[Details]]=$B13)/(Table1[[#This Row],[Details]:[Details]]=$B13)*(ROW(Table1[[Details]:[Details]])-ROW(Table1[[#Headers],[Details]])),COLUMNS($C$10:E12))),"") | F13: =IF(COLUMNS($C$10:F12)<=$A13,INDEX(Table1[[PARTICULAR]:[PARTICULAR]],_xlfn.AGGREGATE(15,3,(Table1[[#This Row],[Details]:[Details]]=$B13)/(Table1[[#This Row],[Details]:[Details]]=$B13)*(ROW(Table1[[Details]:[Details]])-ROW(Table1[[#Headers],[Details]])),COLUMNS($C$10:F12))),"") | G13: =IF(COLUMNS($C$10:G12)<=$A13,INDEX(Table1[[PARTICULAR]:[PARTICULAR]],_xlfn.AGGREGATE(15,3,(Table1[[#This Row],[Details]:[Details]]=$B13)/(Table1[[#This Row],[Details]:[Details]]=$B13)*(ROW(Table1[[Details]:[Details]])-ROW(Table1[[#Headers],[Details]])),COLUMNS($C$10:G12))),"") | H13: =IF(COLUMNS($C$10:H12)<=$A13,INDEX(Table1[[PARTICULAR]:[PARTICULAR]],_xlfn.AGGREGATE(15,3,(Table1[[#This Row],[Details]:[Details]]=$B13)/(Table1[[#This Row],[Details]:[Details]]=$B13)*(ROW(Table1[[Details]:[Details]])-ROW(Table1[[#Headers],[Details]])),COLUMNS($C$10:H12))),"") | I13: =IF(COLUMNS($C$10:I12)<=$A13,INDEX(Table1[[PARTICULAR]:[PARTICULAR]],_xlfn.AGGREGATE(15,3,(Table1[[#This Row],[Details]:[Details]]=$B13)/(Table1[[#This Row],[Details]:[Details]]=$B13)*(ROW(Table1[[Details]:[Details]])-ROW(Table1[[#Headers],[Details]])),COLUMNS($C$10:I12))),"") | J13: =IF(COLUMNS($C$10:J12)<=$A13,INDEX(Table1[[PARTICULAR]:[PARTICULAR]],_xlfn.AGGREGATE(15,3,(Table1[[#This Row],[Details]:[Details]]=$B13)/(Table1[[#This Row],[Details]:[Details]]=$B13)*(ROW(Table1[[Details]:[Details]])-ROW(Table1[[#Headers],[Details]])),COLUMNS($C$10:J12))),"") | ... CB13: =IF(COLUMNS($C$10:CB12)<=$A13,INDEX(Table1[[PARTICULAR]:[PARTICULAR]],_xlfn.AGGREGATE(15,3,(Table1[[#This Row],[Details]:[Details]]=$B13)/(Table1[[#This Row],[Details]:[Details]]=$B13)*(ROW(Table1[[Details]:[Details]])-ROW(Table1[[#Headers],[Details]])),COLUMNS($C$10:CB12))),"")
A14: =COUNTIF(Table1[Details],B14) -> 19 | B14: =IFERROR(INDEX(Table1[Details],MATCH(0,INDEX(COUNTIF($B$10:B13,Table1[Details]),),0)),"") -> Latex | C14: =IF(COLUMNS($C$10:C13)<=$A14,INDEX(Table1[[PARTICULAR]:[PARTICULAR]],_xlfn.AGGREGATE(15,3,(Table1[[#This Row],[Details]:[Details]]=$B14)/(Table1[[#This Row],[Details]:[Details]]=$B14)*(ROW(Table1[[Details]:[Details]])-ROW(Table1[[#Headers],[Details]])),COLUMNS($C$10:C13))),"") -> Latex Print on Canvas | D14: =IF(COLUMNS($C$10:D13)<=$A14,INDEX(Table1[[PARTICULAR]:[PARTICULAR]],_xlfn.AGGREGATE(15,3,(Table1[[#This Row],[Details]:[Details]]=$B14)/(Table1[[#This Row],[Details]:[Details]]=$B14)*(ROW(Table1[[Details]:[Details]])-ROW(Table1[[#Headers],[Details]])),COLUMNS($C$10:D13))),"") -> 2 Side Latex Print on 3mm Sunboard | E14: =IF(COLUMNS($C$10:E13)<=$A14,INDEX(Table1[[PARTICULAR]:[PARTICULAR]],_xlfn.AGGREGATE(15,3,(Table1[[#This Row],[Details]:[Details]]=$B14)/(Table1[[#This Row],[Details]:[Details]]=$B14)*(ROW(Table1[[Details]:[Details]])-ROW(Table1[[#Headers],[Details]])),COLUMNS($C$10:E13))),"") -> 2 Side Latex Print on 5mm Sunboard | F14: =IF(COLUMNS($C$10:F13)<=$A14,INDEX(Table1[[PARTICULAR]:[PARTICULAR]],_xlfn.AGGREGATE(15,3,(Table1[[#This Row],[Details]:[Details]]=$B14)/(Table1[[#This Row],[Details]:[Details]]=$B14)*(ROW(Table1[[Details]:[Details]])-ROW(Table1[[#Headers],[Details]])),COLUMNS($C$10:F13))),"") -> LATEX Backlit Vinyl Print With Lam | G14: =IF(COLUMNS($C$10:G13)<=$A14,INDEX(Table1[[PARTICULAR]:[PARTICULAR]],_xlfn.AGGREGATE(15,3,(Table1[[#This Row],[Details]:[Details]]=$B14)/(Table1[[#This Row],[Details]:[Details]]=$B14)*(ROW(Table1[[Details]:[Details]])-ROW(Table1[[#Headers],[Details]])),COLUMNS($C$10:G13))),"") -> Latex Gray Back with Lamination | H14: =IF(COLUMNS($C$10:H13)<=$A14,INDEX(Table1[[PARTICULAR]:[PARTICULAR]],_xlfn.AGGREGATE(15,3,(Table1[[#This Row],[Details]:[Details]]=$B14)/(Table1[[#This Row],[Details]:[Details]]=$B14)*(ROW(Table1[[Details]:[Details]])-ROW(Table1[[#Headers],[Details]])),COLUMNS($C$10:H13))),"") -> Latex Gray Back with Lam+3mm SB | I14: =IF(COLUMNS($C$10:I13)<=$A14,INDEX(Table1[[PARTICULAR]:[PARTICULAR]],_xlfn.AGGREGATE(15,3,(Table1[[#This Row],[Details]:[Details]]=$B14)/(Table1[[#This Row],[Details]:[Details]]=$B14)*(ROW(Table1[[Details]:[Details]])-ROW(Table1[[#Headers],[Details]])),COLUMNS($C$10:I13))),"") -> Latex Gray Back with Lam+5mm SB | J14: =IF(COLUMNS($C$10:J13)<=$A14,INDEX(Table1[[PARTICULAR]:[PARTICULAR]],_xlfn.AGGREGATE(15,3,(Table1[[#This Row],[Details]:[Details]]=$B14)/(Table1[[#This Row],[Details]:[Details]]=$B14)*(ROW(Table1[[Details]:[Details]])-ROW(Table1[[#Headers],[Details]])),COLUMNS($C$10:J13))),"") -> Latex Translite Vinyl Print With Lam | ... CB14: =IF(COLUMNS($C$10:CB13)<=$A14,INDEX(Table1[[PARTICULAR]:[PARTICULAR]],_xlfn.AGGREGATE(15,3,(Table1[[#This Row],[Details]:[Details]]=$B14)/(Table1[[#This Row],[Details]:[Details]]=$B14)*(ROW(Table1[[Details]:[Details]])-ROW(Table1[[#Headers],[Details]])),COLUMNS($C$10:CB13))),"")
A15: =COUNTIF(Table1[Details],B15) -> 1 | B15: =IFERROR(INDEX(Table1[Details],MATCH(0,INDEX(COUNTIF($B$10:B14,Table1[Details]),),0)),"") -> Carpet | C15: =IF(COLUMNS($C$10:C14)<=$A15,INDEX(Table1[[PARTICULAR]:[PARTICULAR]],_xlfn.AGGREGATE(15,3,(Table1[[#This Row],[Details]:[Details]]=$B15)/(Table1[[#This Row],[Details]:[Details]]=$B15)*(ROW(Table1[[Details]:[Details]])-ROW(Table1[[#Headers],[Details]])),COLUMNS($C$10:C14))),"") -> Floor Carpet | D15: =IF(COLUMNS($C$10:D14)<=$A15,INDEX(Table1[[PARTICULAR]:[PARTICULAR]],_xlfn.AGGREGATE(15,3,(Table1[[#This Row],[Details]:[Details]]=$B15)/(Table1[[#This Row],[Details]:[Details]]=$B15)*(ROW(Table1[[Details]:[Details]])-ROW(Table1[[#Headers],[Details]])),COLUMNS($C$10:D14))),"") | E15: =IF(COLUMNS($C$10:E14)<=$A15,INDEX(Table1[[PARTICULAR]:[PARTICULAR]],_xlfn.AGGREGATE(15,3,(Table1[[#This Row],[Details]:[Details]]=$B15)/(Table1[[#This Row],[Details]:[Details]]=$B15)*(ROW(Table1[[Details]:[Details]])-ROW(Table1[[#Headers],[Details]])),COLUMNS($C$10:E14))),"") | F15: =IF(COLUMNS($C$10:F14)<=$A15,INDEX(Table1[[PARTICULAR]:[PARTICULAR]],_xlfn.AGGREGATE(15,3,(Table1[[#This Row],[Details]:[Details]]=$B15)/(Table1[[#This Row],[Details]:[Details]]=$B15)*(ROW(Table1[[Details]:[Details]])-ROW(Table1[[#Headers],[Details]])),COLUMNS($C$10:F14))),"") | G15: =IF(COLUMNS($C$10:G14)<=$A15,INDEX(Table1[[PARTICULAR]:[PARTICULAR]],_xlfn.AGGREGATE(15,3,(Table1[[#This Row],[Details]:[Details]]=$B15)/(Table1[[#This Row],[Details]:[Details]]=$B15)*(ROW(Table1[[Details]:[Details]])-ROW(Table1[[#Headers],[Details]])),COLUMNS($C$10:G14))),"") | H15: =IF(COLUMNS($C$10:H14)<=$A15,INDEX(Table1[[PARTICULAR]:[PARTICULAR]],_xlfn.AGGREGATE(15,3,(Table1[[#This Row],[Details]:[Details]]=$B15)/(Table1[[#This Row],[Details]:[Details]]=$B15)*(ROW(Table1[[Details]:[Details]])-ROW(Table1[[#Headers],[Details]])),COLUMNS($C$10:H14))),"") | I15: =IF(COLUMNS($C$10:I14)<=$A15,INDEX(Table1[[PARTICULAR]:[PARTICULAR]],_xlfn.AGGREGATE(15,3,(Table1[[#This Row],[Details]:[Details]]=$B15)/(Table1[[#This Row],[Details]:[Details]]=$B15)*(ROW(Table1[[Details]:[Details]])-ROW(Table1[[#Headers],[Details]])),COLUMNS($C$10:I14))),"") | J15: =IF(COLUMNS($C$10:J14)<=$A15,INDEX(Table1[[PARTICULAR]:[PARTICULAR]],_xlfn.AGGREGATE(15,3,(Table1[[#This Row],[Details]:[Details]]=$B15)/(Table1[[#This Row],[Details]:[Details]]=$B15)*(ROW(Table1[[Details]:[Details]])-ROW(Table1[[#Headers],[Details]])),COLUMNS($C$10:J14))),"") | ... CB15: =IF(COLUMNS($C$10:CB14)<=$A15,INDEX(Table1[[PARTICULAR]:[PARTICULAR]],_xlfn.AGGREGATE(15,3,(Table1[[#This Row],[Details]:[Details]]=$B15)/(Table1[[#This Row],[Details]:[Details]]=$B15)*(ROW(Table1[[Details]:[Details]])-ROW(Table1[[#Headers],[Details]])),COLUMNS($C$10:CB14))),"")
A16: =COUNTIF(Table1[Details],B16) -> 15 | B16: =IFERROR(INDEX(Table1[Details],MATCH(0,INDEX(COUNTIF($B$10:B15,Table1[Details]),),0)),"") -> Vinyl | C16: =IF(COLUMNS($C$10:C15)<=$A16,INDEX(Table1[[PARTICULAR]:[PARTICULAR]],_xlfn.AGGREGATE(15,3,(Table1[[#This Row],[Details]:[Details]]=$B16)/(Table1[[#This Row],[Details]:[Details]]=$B16)*(ROW(Table1[[Details]:[Details]])-ROW(Table1[[#Headers],[Details]])),COLUMNS($C$10:C15))),"") -> Clear Vinyl Printing | D16: =IF(COLUMNS($C$10:D15)<=$A16,INDEX(Table1[[PARTICULAR]:[PARTICULAR]],_xlfn.AGGREGATE(15,3,(Table1[[#This Row],[Details]:[Details]]=$B16)/(Table1[[#This Row],[Details]:[Details]]=$B16)*(ROW(Table1[[Details]:[Details]])-ROW(Table1[[#Headers],[Details]])),COLUMNS($C$10:D15))),"") -> Frosted Vinyl Cutting | E16: =IF(COLUMNS($C$10:E15)<=$A16,INDEX(Table1[[PARTICULAR]:[PARTICULAR]],_xlfn.AGGREGATE(15,3,(Table1[[#This Row],[Details]:[Details]]=$B16)/(Table1[[#This Row],[Details]:[Details]]=$B16)*(ROW(Table1[[Details]:[Details]])-ROW(Table1[[#Headers],[Details]])),COLUMNS($C$10:E15))),"") -> 3M Frosted Vinyl | F16: =IF(COLUMNS($C$10:F15)<=$A16,INDEX(Table1[[PARTICULAR]:[PARTICULAR]],_xlfn.AGGREGATE(15,3,(Table1[[#This Row],[Details]:[Details]]=$B16)/(Table1[[#This Row],[Details]:[Details]]=$B16)*(ROW(Table1[[Details]:[Details]])-ROW(Table1[[#Headers],[Details]])),COLUMNS($C$10:F15))),"") -> Lamination | G16: =IF(COLUMNS($C$10:G15)<=$A16,INDEX(Table1[[PARTICULAR]:[PARTICULAR]],_xlfn.AGGREGATE(15,3,(Table1[[#This Row],[Details]:[Details]]=$B16)/(Table1[[#This Row],[Details]:[Details]]=$B16)*(ROW(Table1[[Details]:[Details]])-ROW(Table1[[#Headers],[Details]])),COLUMNS($C$10:G15))),"") -> BLACK VINYL | H16: =IF(COLUMNS($C$10:H15)<=$A16,INDEX(Table1[[PARTICULAR]:[PARTICULAR]],_xlfn.AGGREGATE(15,3,(Table1[[#This Row],[Details]:[Details]]=$B16)/(Table1[[#This Row],[Details]:[Details]]=$B16)*(ROW(Table1[[Details]:[Details]])-ROW(Table1[[#Headers],[Details]])),COLUMNS($C$10:H15))),"") -> GOLDEN BRUSH VINYL | I16: =IF(COLUMNS($C$10:I15)<=$A16,INDEX(Table1[[PARTICULAR]:[PARTICULAR]],_xlfn.AGGREGATE(15,3,(Table1[[#This Row],[Details]:[Details]]=$B16)/(Table1[[#This Row],[Details]:[Details]]=$B16)*(ROW(Table1[[Details]:[Details]])-ROW(Table1[[#Headers],[Details]])),COLUMNS($C$10:I15))),"") -> Grey Back Vinyl | J16: =IF(COLUMNS($C$10:J15)<=$A16,INDEX(Table1[[PARTICULAR]:[PARTICULAR]],_xlfn.AGGREGATE(15,3,(Table1[[#This Row],[Details]:[Details]]=$B16)/(Table1[[#This Row],[Details]:[Details]]=$B16)*(ROW(Table1[[Details]:[Details]])-ROW(Table1[[#Headers],[Details]])),COLUMNS($C$10:J15))),"") -> Plain Frosted Vinyl | ... CB16: =IF(COLUMNS($C$10:CB15)<=$A16,INDEX(Table1[[PARTICULAR]:[PARTICULAR]],_xlfn.AGGREGATE(15,3,(Table1[[#This Row],[Details]:[Details]]=$B16)/(Table1[[#This Row],[Details]:[Details]]=$B16)*(ROW(Table1[[Details]:[Details]])-ROW(Table1[[#Headers],[Details]])),COLUMNS($C$10:CB15))),"")
A17: =COUNTIF(Table1[Details],B17) -> 3 | B17: =IFERROR(INDEX(Table1[Details],MATCH(0,INDEX(COUNTIF($B$10:B16,Table1[Details]),),0)),"") -> Fabric | C17: =IF(COLUMNS($C$10:C16)<=$A17,INDEX(Table1[[PARTICULAR]:[PARTICULAR]],_xlfn.AGGREGATE(15,3,(Table1[[#This Row],[Details]:[Details]]=$B17)/(Table1[[#This Row],[Details]:[Details]]=$B17)*(ROW(Table1[[Details]:[Details]])-ROW(Table1[[#Headers],[Details]])),COLUMNS($C$10:C16))),"") -> FABRIC PRINT WITH SILICON TAPE & STITCHI | D17: =IF(COLUMNS($C$10:D16)<=$A17,INDEX(Table1[[PARTICULAR]:[PARTICULAR]],_xlfn.AGGREGATE(15,3,(Table1[[#This Row],[Details]:[Details]]=$B17)/(Table1[[#This Row],[Details]:[Details]]=$B17)*(ROW(Table1[[Details]:[Details]])-ROW(Table1[[#Headers],[Details]])),COLUMNS($C$10:D16))),"") -> Organza Fabric white Color | E17: =IF(COLUMNS($C$10:E16)<=$A17,INDEX(Table1[[PARTICULAR]:[PARTICULAR]],_xlfn.AGGREGATE(15,3,(Table1[[#This Row],[Details]:[Details]]=$B17)/(Table1[[#This Row],[Details]:[Details]]=$B17)*(ROW(Table1[[Details]:[Details]])-ROW(Table1[[#Headers],[Details]])),COLUMNS($C$10:E16))),"") -> UV PRINTED POLYESTER BACKLIT FABRIC | F17: =IF(COLUMNS($C$10:F16)<=$A17,INDEX(Table1[[PARTICULAR]:[PARTICULAR]],_xlfn.AGGREGATE(15,3,(Table1[[#This Row],[Details]:[Details]]=$B17)/(Table1[[#This Row],[Details]:[Details]]=$B17)*(ROW(Table1[[Details]:[Details]])-ROW(Table1[[#Headers],[Details]])),COLUMNS($C$10:F16))),"") | G17: =IF(COLUMNS($C$10:G16)<=$A17,INDEX(Table1[[PARTICULAR]:[PARTICULAR]],_xlfn.AGGREGATE(15,3,(Table1[[#This Row],[Details]:[Details]]=$B17)/(Table1[[#This Row],[Details]:[Details]]=$B17)*(ROW(Table1[[Details]:[Details]])-ROW(Table1[[#Headers],[Details]])),COLUMNS($C$10:G16))),"") | H17: =IF(COLUMNS($C$10:H16)<=$A17,INDEX(Table1[[PARTICULAR]:[PARTICULAR]],_xlfn.AGGREGATE(15,3,(Table1[[#This Row],[Details]:[Details]]=$B17)/(Table1[[#This Row],[Details]:[Details]]=$B17)*(ROW(Table1[[Details]:[Details]])-ROW(Table1[[#Headers],[Details]])),COLUMNS($C$10:H16))),"") | I17: =IF(COLUMNS($C$10:I16)<=$A17,INDEX(Table1[[PARTICULAR]:[PARTICULAR]],_xlfn.AGGREGATE(15,3,(Table1[[#This Row],[Details]:[Details]]=$B17)/(Table1[[#This Row],[Details]:[Details]]=$B17)*(ROW(Table1[[Details]:[Details]])-ROW(Table1[[#Headers],[Details]])),COLUMNS($C$10:I16))),"") | J17: =IF(COLUMNS($C$10:J16)<=$A17,INDEX(Table1[[PARTICULAR]:[PARTICULAR]],_xlfn.AGGREGATE(15,3,(Table1[[#This Row],[Details]:[Details]]=$B17)/(Table1[[#This Row],[Details]:[Details]]=$B17)*(ROW(Table1[[Details]:[Details]])-ROW(Table1[[#Headers],[Details]])),COLUMNS($C$10:J16))),"") | ... CB17: =IF(COLUMNS($C$10:CB16)<=$A17,INDEX(Table1[[PARTICULAR]:[PARTICULAR]],_xlfn.AGGREGATE(15,3,(Table1[[#This Row],[Details]:[Details]]=$B17)/(Table1[[#This Row],[Details]:[Details]]=$B17)*(ROW(Table1[[Details]:[Details]])-ROW(Table1[[#Headers],[Details]])),COLUMNS($C$10:CB16))),"")
A18: =COUNTIF(Table1[Details],B18) -> 9 | B18: =IFERROR(INDEX(Table1[Details],MATCH(0,INDEX(COUNTIF($B$10:B17,Table1[Details]),),0)),"") -> Flex | C18: =IF(COLUMNS($C$10:C17)<=$A18,INDEX(Table1[[PARTICULAR]:[PARTICULAR]],_xlfn.AGGREGATE(15,3,(Table1[[#This Row],[Details]:[Details]]=$B18)/(Table1[[#This Row],[Details]:[Details]]=$B18)*(ROW(Table1[[Details]:[Details]])-ROW(Table1[[#Headers],[Details]])),COLUMNS($C$10:C17))),"") -> Star Flex Eco solvent Print | D18: =IF(COLUMNS($C$10:D17)<=$A18,INDEX(Table1[[PARTICULAR]:[PARTICULAR]],_xlfn.AGGREGATE(15,3,(Table1[[#This Row],[Details]:[Details]]=$B18)/(Table1[[#This Row],[Details]:[Details]]=$B18)*(ROW(Table1[[Details]:[Details]])-ROW(Table1[[#Headers],[Details]])),COLUMNS($C$10:D17))),"") -> Plain Flex | E18: =IF(COLUMNS($C$10:E17)<=$A18,INDEX(Table1[[PARTICULAR]:[PARTICULAR]],_xlfn.AGGREGATE(15,3,(Table1[[#This Row],[Details]:[Details]]=$B18)/(Table1[[#This Row],[Details]:[Details]]=$B18)*(ROW(Table1[[Details]:[Details]])-ROW(Table1[[#Headers],[Details]])),COLUMNS($C$10:E17))),"") -> Backlit Flex Printing | F18: =IF(COLUMNS($C$10:F17)<=$A18,INDEX(Table1[[PARTICULAR]:[PARTICULAR]],_xlfn.AGGREGATE(15,3,(Table1[[#This Row],[Details]:[Details]]=$B18)/(Table1[[#This Row],[Details]:[Details]]=$B18)*(ROW(Table1[[Details]:[Details]])-ROW(Table1[[#Headers],[Details]])),COLUMNS($C$10:F17))),"") -> BACKLIT FLEX PRINT-16 OZ | G18: =IF(COLUMNS($C$10:G17)<=$A18,INDEX(Table1[[PARTICULAR]:[PARTICULAR]],_xlfn.AGGREGATE(15,3,(Table1[[#This Row],[Details]:[Details]]=$B18)/(Table1[[#This Row],[Details]:[Details]]=$B18)*(ROW(Table1[[Details]:[Details]])-ROW(Table1[[#Headers],[Details]])),COLUMNS($C$10:G17))),"") -> Frontlit Flex Printing | H18: =IF(COLUMNS($C$10:H17)<=$A18,INDEX(Table1[[PARTICULAR]:[PARTICULAR]],_xlfn.AGGREGATE(15,3,(Table1[[#This Row],[Details]:[Details]]=$B18)/(Table1[[#This Row],[Details]:[Details]]=$B18)*(ROW(Table1[[Details]:[Details]])-ROW(Table1[[#Headers],[Details]])),COLUMNS($C$10:H17))),"") -> Frontlit Flex Print On Branded Media | I18: =IF(COLUMNS($C$10:I17)<=$A18,INDEX(Table1[[PARTICULAR]:[PARTICULAR]],_xlfn.AGGREGATE(15,3,(Table1[[#This Row],[Details]:[Details]]=$B18)/(Table1[[#This Row],[Details]:[Details]]=$B18)*(ROW(Table1[[Details]:[Details]])-ROW(Table1[[#Headers],[Details]])),COLUMNS($C$10:I17))),"") -> PVC Flex | J18: =IF(COLUMNS($C$10:J17)<=$A18,INDEX(Table1[[PARTICULAR]:[PARTICULAR]],_xlfn.AGGREGATE(15,3,(Table1[[#This Row],[Details]:[Details]]=$B18)/(Table1[[#This Row],[Details]:[Details]]=$B18)*(ROW(Table1[[Details]:[Details]])-ROW(Table1[[#Headers],[Details]])),COLUMNS($C$10:J17))),"") -> Flex Mounting & Fitting Charges | ... CB18: =IF(COLUMNS($C$10:CB17)<=$A18,INDEX(Table1[[PARTICULAR]:[PARTICULAR]],_xlfn.AGGREGATE(15,3,(Table1[[#This Row],[Details]:[Details]]=$B18)/(Table1[[#This Row],[Details]:[Details]]=$B18)*(ROW(Table1[[Details]:[Details]])-ROW(Table1[[#Headers],[Details]])),COLUMNS($C$10:CB17))),"")
A19: =COUNTIF(Table1[Details],B19) -> 33 | B19: =IFERROR(INDEX(Table1[Details],MATCH(0,INDEX(COUNTIF($B$10:B18,Table1[Details]),),0)),"") -> Light/Festive | C19: =IF(COLUMNS($C$10:C18)<=$A19,INDEX(Table1[[PARTICULAR]:[PARTICULAR]],_xlfn.AGGREGATE(15,3,(Table1[[#This Row],[Details]:[Details]]=$B19)/(Table1[[#This Row],[Details]:[Details]]=$B19)*(ROW(Table1[[Details]:[Details]])-ROW(Table1[[#Headers],[Details]])),COLUMNS($C$10:C18))),"") -> TUBELIGHT,CHOWK & WIRING | D19: =IF(COLUMNS($C$10:D18)<=$A19,INDEX(Table1[[PARTICULAR]:[PARTICULAR]],_xlfn.AGGREGATE(15,3,(Table1[[#This Row],[Details]:[Details]]=$B19)/(Table1[[#This Row],[Details]:[Details]]=$B19)*(ROW(Table1[[Details]:[Details]])-ROW(Table1[[#Headers],[Details]])),COLUMNS($C$10:D18))),"") -> 1.2mm Rope Wire | E19: =IF(COLUMNS($C$10:E18)<=$A19,INDEX(Table1[[PARTICULAR]:[PARTICULAR]],_xlfn.AGGREGATE(15,3,(Table1[[#This Row],[Details]:[Details]]=$B19)/(Table1[[#This Row],[Details]:[Details]]=$B19)*(ROW(Table1[[Details]:[Details]])-ROW(Table1[[#Headers],[Details]])),COLUMNS($C$10:E18))),"") -> 250W LED Drivers | F19: =IF(COLUMNS($C$10:F18)<=$A19,INDEX(Table1[[PARTICULAR]:[PARTICULAR]],_xlfn.AGGREGATE(15,3,(Table1[[#This Row],[Details]:[Details]]=$B19)/(Table1[[#This Row],[Details]:[Details]]=$B19)*(ROW(Table1[[Details]:[Details]])-ROW(Table1[[#Headers],[Details]])),COLUMNS($C$10:F18))),"") -> Aluminium Profile Fabric LIT Box | G19: =IF(COLUMNS($C$10:G18)<=$A19,INDEX(Table1[[PARTICULAR]:[PARTICULAR]],_xlfn.AGGREGATE(15,3,(Table1[[#This Row],[Details]:[Details]]=$B19)/(Table1[[#This Row],[Details]:[Details]]=$B19)*(ROW(Table1[[Details]:[Details]])-ROW(Table1[[#Headers],[Details]])),COLUMNS($C$10:G18))),"") -> Arch Gate MS HB | H19: =IF(COLUMNS($C$10:H18)<=$A19,INDEX(Table1[[PARTICULAR]:[PARTICULAR]],_xlfn.AGGREGATE(15,3,(Table1[[#This Row],[Details]:[Details]]=$B19)/(Table1[[#This Row],[Details]:[Details]]=$B19)*(ROW(Table1[[Details]:[Details]])-ROW(Table1[[#Headers],[Details]])),COLUMNS($C$10:H18))),"") -> Arch Gate MS LB | I19: =IF(COLUMNS($C$10:I18)<=$A19,INDEX(Table1[[PARTICULAR]:[PARTICULAR]],_xlfn.AGGREGATE(15,3,(Table1[[#This Row],[Details]:[Details]]=$B19)/(Table1[[#This Row],[Details]:[Details]]=$B19)*(ROW(Table1[[Details]:[Details]])-ROW(Table1[[#Headers],[Details]])),COLUMNS($C$10:I18))),"") -> Arch Gate MS MB | J19: =IF(COLUMNS($C$10:J18)<=$A19,INDEX(Table1[[PARTICULAR]:[PARTICULAR]],_xlfn.AGGREGATE(15,3,(Table1[[#This Row],[Details]:[Details]]=$B19)/(Table1[[#This Row],[Details]:[Details]]=$B19)*(ROW(Table1[[Details]:[Details]])-ROW(Table1[[#Headers],[Details]])),COLUMNS($C$10:J18))),"") -> Dangler 3F | ... CB19: =IF(COLUMNS($C$10:CB18)<=$A19,INDEX(Table1[[PARTICULAR]:[PARTICULAR]],_xlfn.AGGREGATE(15,3,(Table1[[#This Row],[Details]:[Details]]=$B19)/(Table1[[#This Row],[Details]:[Details]]=$B19)*(ROW(Table1[[Details]:[Details]])-ROW(Table1[[#Headers],[Details]])),COLUMNS($C$10:CB18))),"")
A20: =COUNTIF(Table1[Details],B20) -> 8 | B20: =IFERROR(INDEX(Table1[Details],MATCH(0,INDEX(COUNTIF($B$10:B19,Table1[Details]),),0)),"") -> Metal | C20: =IF(COLUMNS($C$10:C19)<=$A20,INDEX(Table1[[PARTICULAR]:[PARTICULAR]],_xlfn.AGGREGATE(15,3,(Table1[[#This Row],[Details]:[Details]]=$B20)/(Table1[[#This Row],[Details]:[Details]]=$B20)*(ROW(Table1[[Details]:[Details]])-ROW(Table1[[#Headers],[Details]])),COLUMNS($C$10:C19))),"") -> J Hook | D20: =IF(COLUMNS($C$10:D19)<=$A20,INDEX(Table1[[PARTICULAR]:[PARTICULAR]],_xlfn.AGGREGATE(15,3,(Table1[[#This Row],[Details]:[Details]]=$B20)/(Table1[[#This Row],[Details]:[Details]]=$B20)*(ROW(Table1[[Details]:[Details]])-ROW(Table1[[#Headers],[Details]])),COLUMNS($C$10:D19))),"") -> S Hook | E20: =IF(COLUMNS($C$10:E19)<=$A20,INDEX(Table1[[PARTICULAR]:[PARTICULAR]],_xlfn.AGGREGATE(15,3,(Table1[[#This Row],[Details]:[Details]]=$B20)/(Table1[[#This Row],[Details]:[Details]]=$B20)*(ROW(Table1[[Details]:[Details]])-ROW(Table1[[#Headers],[Details]])),COLUMNS($C$10:E19))),"") -> MODULAR FIXTURE 4FT X 7FT | F20: =IF(COLUMNS($C$10:F19)<=$A20,INDEX(Table1[[PARTICULAR]:[PARTICULAR]],_xlfn.AGGREGATE(15,3,(Table1[[#This Row],[Details]:[Details]]=$B20)/(Table1[[#This Row],[Details]:[Details]]=$B20)*(ROW(Table1[[Details]:[Details]])-ROW(Table1[[#Headers],[Details]])),COLUMNS($C$10:F19))),"") -> MODULAR FIXTURE 4FT X 8FT | G20: =IF(COLUMNS($C$10:G19)<=$A20,INDEX(Table1[[PARTICULAR]:[PARTICULAR]],_xlfn.AGGREGATE(15,3,(Table1[[#This Row],[Details]:[Details]]=$B20)/(Table1[[#This Row],[Details]:[Details]]=$B20)*(ROW(Table1[[Details]:[Details]])-ROW(Table1[[#Headers],[Details]])),COLUMNS($C$10:G19))),"") -> MS Frame Standee Structure | H20: =IF(COLUMNS($C$10:H19)<=$A20,INDEX(Table1[[PARTICULAR]:[PARTICULAR]],_xlfn.AGGREGATE(15,3,(Table1[[#This Row],[Details]:[Details]]=$B20)/(Table1[[#This Row],[Details]:[Details]]=$B20)*(ROW(Table1[[Details]:[Details]])-ROW(Table1[[#Headers],[Details]])),COLUMNS($C$10:H19))),"") -> MS Frame Standee(Wrought Iron) | I20: =IF(COLUMNS($C$10:I19)<=$A20,INDEX(Table1[[PARTICULAR]:[PARTICULAR]],_xlfn.AGGREGATE(15,3,(Table1[[#This Row],[Details]:[Details]]=$B20)/(Table1[[#This Row],[Details]:[Details]]=$B20)*(ROW(Table1[[Details]:[Details]])-ROW(Table1[[#Headers],[Details]])),COLUMNS($C$10:I19))),"") -> MS Frame Structure | J20: =IF(COLUMNS($C$10:J19)<=$A20,INDEX(Table1[[PARTICULAR]:[PARTICULAR]],_xlfn.AGGREGATE(15,3,(Table1[[#This Row],[Details]:[Details]]=$B20)/(Table1[[#This Row],[Details]:[Details]]=$B20)*(ROW(Table1[[Details]:[Details]])-ROW(Table1[[#Headers],[Details]])),COLUMNS($C$10:J19))),"") -> Store Directory | ... CB20: =IF(COLUMNS($C$10:CB19)<=$A20,INDEX(Table1[[PARTICULAR]:[PARTICULAR]],_xlfn.AGGREGATE(15,3,(Table1[[#This Row],[Details]:[Details]]=$B20)/(Table1[[#This Row],[Details]:[Details]]=$B20)*(ROW(Table1[[Details]:[Details]])-ROW(Table1[[#Headers],[Details]])),COLUMNS($C$10:CB19))),"")
A21: =COUNTIF(Table1[Details],B21) -> 9 | B21: =IFERROR(INDEX(Table1[Details],MATCH(0,INDEX(COUNTIF($B$10:B20,Table1[Details]),),0)),"") -> Digital | C21: =IF(COLUMNS($C$10:C20)<=$A21,INDEX(Table1[[PARTICULAR]:[PARTICULAR]],_xlfn.AGGREGATE(15,3,(Table1[[#This Row],[Details]:[Details]]=$B21)/(Table1[[#This Row],[Details]:[Details]]=$B21)*(ROW(Table1[[Details]:[Details]])-ROW(Table1[[#Headers],[Details]])),COLUMNS($C$10:C20))),"") -> A3 - Danglers - Digital | D21: =IF(COLUMNS($C$10:D20)<=$A21,INDEX(Table1[[PARTICULAR]:[PARTICULAR]],_xlfn.AGGREGATE(15,3,(Table1[[#This Row],[Details]:[Details]]=$B21)/(Table1[[#This Row],[Details]:[Details]]=$B21)*(ROW(Table1[[Details]:[Details]])-ROW(Table1[[#Headers],[Details]])),COLUMNS($C$10:D20))),"") -> A3 - Signage - Digital | E21: =IF(COLUMNS($C$10:E20)<=$A21,INDEX(Table1[[PARTICULAR]:[PARTICULAR]],_xlfn.AGGREGATE(15,3,(Table1[[#This Row],[Details]:[Details]]=$B21)/(Table1[[#This Row],[Details]:[Details]]=$B21)*(ROW(Table1[[Details]:[Details]])-ROW(Table1[[#Headers],[Details]])),COLUMNS($C$10:E20))),"") -> A4 - Signage - Digital | F21: =IF(COLUMNS($C$10:F20)<=$A21,INDEX(Table1[[PARTICULAR]:[PARTICULAR]],_xlfn.AGGREGATE(15,3,(Table1[[#This Row],[Details]:[Details]]=$B21)/(Table1[[#This Row],[Details]:[Details]]=$B21)*(ROW(Table1[[Details]:[Details]])-ROW(Table1[[#Headers],[Details]])),COLUMNS($C$10:F20))),"") -> A5 - Signage - Digital | G21: =IF(COLUMNS($C$10:G20)<=$A21,INDEX(Table1[[PARTICULAR]:[PARTICULAR]],_xlfn.AGGREGATE(15,3,(Table1[[#This Row],[Details]:[Details]]=$B21)/(Table1[[#This Row],[Details]:[Details]]=$B21)*(ROW(Table1[[Details]:[Details]])-ROW(Table1[[#Headers],[Details]])),COLUMNS($C$10:G20))),"") -> Shelf Talker 6" X 8" - Digital | H21: =IF(COLUMNS($C$10:H20)<=$A21,INDEX(Table1[[PARTICULAR]:[PARTICULAR]],_xlfn.AGGREGATE(15,3,(Table1[[#This Row],[Details]:[Details]]=$B21)/(Table1[[#This Row],[Details]:[Details]]=$B21)*(ROW(Table1[[Details]:[Details]])-ROW(Table1[[#Headers],[Details]])),COLUMNS($C$10:H20))),"") -> Wobbler Printing - Digital | I21: =IF(COLUMNS($C$10:I20)<=$A21,INDEX(Table1[[PARTICULAR]:[PARTICULAR]],_xlfn.AGGREGATE(15,3,(Table1[[#This Row],[Details]:[Details]]=$B21)/(Table1[[#This Row],[Details]:[Details]]=$B21)*(ROW(Table1[[Details]:[Details]])-ROW(Table1[[#Headers],[Details]])),COLUMNS($C$10:I20))),"") -> A2 - SIGNAGE - DIGITAL 300GSM | J21: =IF(COLUMNS($C$10:J20)<=$A21,INDEX(Table1[[PARTICULAR]:[PARTICULAR]],_xlfn.AGGREGATE(15,3,(Table1[[#This Row],[Details]:[Details]]=$B21)/(Table1[[#This Row],[Details]:[Details]]=$B21)*(ROW(Table1[[Details]:[Details]])-ROW(Table1[[#Headers],[Details]])),COLUMNS($C$10:J20))),"") -> A3 Sticker Paper | ... CB21: =IF(COLUMNS($C$10:CB20)<=$A21,INDEX(Table1[[PARTICULAR]:[PARTICULAR]],_xlfn.AGGREGATE(15,3,(Table1[[#This Row],[Details]:[Details]]=$B21)/(Table1[[#This Row],[Details]:[Details]]=$B21)*(ROW(Table1[[Details]:[Details]])-ROW(Table1[[#Headers],[Details]])),COLUMNS($C$10:CB20))),"")
A22: =COUNTIF(Table1[Details],B22) -> 14 | B22: =IFERROR(INDEX(Table1[Details],MATCH(0,INDEX(COUNTIF($B$10:B21,Table1[Details]),),0)),"") -> Offset | C22: =IF(COLUMNS($C$10:C21)<=$A22,INDEX(Table1[[PARTICULAR]:[PARTICULAR]],_xlfn.AGGREGATE(15,3,(Table1[[#This Row],[Details]:[Details]]=$B22)/(Table1[[#This Row],[Details]:[Details]]=$B22)*(ROW(Table1[[Details]:[Details]])-ROW(Table1[[#Headers],[Details]])),COLUMNS($C$10:C21))),"") -> A3 - Danglers - Offset | D22: =IF(COLUMNS($C$10:D21)<=$A22,INDEX(Table1[[PARTICULAR]:[PARTICULAR]],_xlfn.AGGREGATE(15,3,(Table1[[#This Row],[Details]:[Details]]=$B22)/(Table1[[#This Row],[Details]:[Details]]=$B22)*(ROW(Table1[[Details]:[Details]])-ROW(Table1[[#Headers],[Details]])),COLUMNS($C$10:D21))),"") -> A4 - Signage - Offset | E22: =IF(COLUMNS($C$10:E21)<=$A22,INDEX(Table1[[PARTICULAR]:[PARTICULAR]],_xlfn.AGGREGATE(15,3,(Table1[[#This Row],[Details]:[Details]]=$B22)/(Table1[[#This Row],[Details]:[Details]]=$B22)*(ROW(Table1[[Details]:[Details]])-ROW(Table1[[#Headers],[Details]])),COLUMNS($C$10:E21))),"") -> A5 - Signage - Offset | F22: =IF(COLUMNS($C$10:F21)<=$A22,INDEX(Table1[[PARTICULAR]:[PARTICULAR]],_xlfn.AGGREGATE(15,3,(Table1[[#This Row],[Details]:[Details]]=$B22)/(Table1[[#This Row],[Details]:[Details]]=$B22)*(ROW(Table1[[Details]:[Details]])-ROW(Table1[[#Headers],[Details]])),COLUMNS($C$10:F21))),"") -> Shelf Talker 2" X 5.5" - Offset | G22: =IF(COLUMNS($C$10:G21)<=$A22,INDEX(Table1[[PARTICULAR]:[PARTICULAR]],_xlfn.AGGREGATE(15,3,(Table1[[#This Row],[Details]:[Details]]=$B22)/(Table1[[#This Row],[Details]:[Details]]=$B22)*(ROW(Table1[[Details]:[Details]])-ROW(Table1[[#Headers],[Details]])),COLUMNS($C$10:G21))),"") -> Shelf Talker 6" X 8" - Offset | H22: =IF(COLUMNS($C$10:H21)<=$A22,INDEX(Table1[[PARTICULAR]:[PARTICULAR]],_xlfn.AGGREGATE(15,3,(Table1[[#This Row],[Details]:[Details]]=$B22)/(Table1[[#This Row],[Details]:[Details]]=$B22)*(ROW(Table1[[Details]:[Details]])-ROW(Table1[[#Headers],[Details]])),COLUMNS($C$10:H21))),"") -> Blank Signage Paper - A4 | I22: =IF(COLUMNS($C$10:I21)<=$A22,INDEX(Table1[[PARTICULAR]:[PARTICULAR]],_xlfn.AGGREGATE(15,3,(Table1[[#This Row],[Details]:[Details]]=$B22)/(Table1[[#This Row],[Details]:[Details]]=$B22)*(ROW(Table1[[Details]:[Details]])-ROW(Table1[[#Headers],[Details]])),COLUMNS($C$10:I21))),"") -> Blank Signage Paper - A5 | J22: =IF(COLUMNS($C$10:J21)<=$A22,INDEX(Table1[[PARTICULAR]:[PARTICULAR]],_xlfn.AGGREGATE(15,3,(Table1[[#This Row],[Details]:[Details]]=$B22)/(Table1[[#This Row],[Details]:[Details]]=$B22)*(ROW(Table1[[Details]:[Details]])-ROW(Table1[[#Headers],[Details]])),COLUMNS($C$10:J21))),"") -> A3 Generic Signage Offset | ... CB22: =IF(COLUMNS($C$10:CB21)<=$A22,INDEX(Table1[[PARTICULAR]:[PARTICULAR]],_xlfn.AGGREGATE(15,3,(Table1[[#This Row],[Details]:[Details]]=$B22)/(Table1[[#This Row],[Details]:[Details]]=$B22)*(ROW(Table1[[Details]:[Details]])-ROW(Table1[[#Headers],[Details]])),COLUMNS($C$10:CB21))),"")
... A34: =COUNTIF(Table1[Details],B34) -> 1 | B34: =IFERROR(INDEX(Table1[Details],MATCH(0,INDEX(COUNTIF($B$10:B33,Table1[Details]),),0)),"") -> T shirt | C34: =IF(COLUMNS($C$10:C33)<=$A34,INDEX(Table1[[PARTICULAR]:[PARTICULAR]],_xlfn.AGGREGATE(15,3,(Table1[[#This Row],[Details]:[Details]]=$B34)/(Table1[[#This Row],[Details]:[Details]]=$B34)*(ROW(Table1[[Details]:[Details]])-ROW(Table1[[#Headers],[Details]])),COLUMNS($C$10:C33))),"") -> T SHIRT | D34: =IF(COLUMNS($C$10:D33)<=$A34,INDEX(Table1[[PARTICULAR]:[PARTICULAR]],_xlfn.AGGREGATE(15,3,(Table1[[#This Row],[Details]:[Details]]=$B34)/(Table1[[#This Row],[Details]:[Details]]=$B34)*(ROW(Table1[[Details]:[Details]])-ROW(Table1[[#Headers],[Details]])),COLUMNS($C$10:D33))),"") | E34: =IF(COLUMNS($C$10:E33)<=$A34,INDEX(Table1[[PARTICULAR]:[PARTICULAR]],_xlfn.AGGREGATE(15,3,(Table1[[#This Row],[Details]:[Details]]=$B34)/(Table1[[#This Row],[Details]:[Details]]=$B34)*(ROW(Table1[[Details]:[Details]])-ROW(Table1[[#Headers],[Details]])),COLUMNS($C$10:E33))),"") | F34: =IF(COLUMNS($C$10:F33)<=$A34,INDEX(Table1[[PARTICULAR]:[PARTICULAR]],_xlfn.AGGREGATE(15,3,(Table1[[#This Row],[Details]:[Details]]=$B34)/(Table1[[#This Row],[Details]:[Details]]=$B34)*(ROW(Table1[[Details]:[Details]])-ROW(Table1[[#Headers],[Details]])),COLUMNS($C$10:F33))),"") | G34: =IF(COLUMNS($C$10:G33)<=$A34,INDEX(Table1[[PARTICULAR]:[PARTICULAR]],_xlfn.AGGREGATE(15,3,(Table1[[#This Row],[Details]:[Details]]=$B34)/(Table1[[#This Row],[Details]:[Details]]=$B34)*(ROW(Table1[[Details]:[Details]])-ROW(Table1[[#Headers],[Details]])),COLUMNS($C$10:G33))),"") | H34: =IF(COLUMNS($C$10:H33)<=$A34,INDEX(Table1[[PARTICULAR]:[PARTICULAR]],_xlfn.AGGREGATE(15,3,(Table1[[#This Row],[Details]:[Details]]=$B34)/(Table1[[#This Row],[Details]:[Details]]=$B34)*(ROW(Table1[[Details]:[Details]])-ROW(Table1[[#Headers],[Details]])),COLUMNS($C$10:H33))),"") | I34: =IF(COLUMNS($C$10:I33)<=$A34,INDEX(Table1[[PARTICULAR]:[PARTICULAR]],_xlfn.AGGREGATE(15,3,(Table1[[#This Row],[Details]:[Details]]=$B34)/(Table1[[#This Row],[Details]:[Details]]=$B34)*(ROW(Table1[[Details]:[Details]])-ROW(Table1[[#Headers],[Details]])),COLUMNS($C$10:I33))),"") | J34: =IF(COLUMNS($C$10:J33)<=$A34,INDEX(Table1[[PARTICULAR]:[PARTICULAR]],_xlfn.AGGREGATE(15,3,(Table1[[#This Row],[Details]:[Details]]=$B34)/(Table1[[#This Row],[Details]:[Details]]=$B34)*(ROW(Table1[[Details]:[Details]])-ROW(Table1[[#Headers],[Details]])),COLUMNS($C$10:J33))),"") | ... CB34: =IF(COLUMNS($C$10:CB33)<=$A34,INDEX(Table1[[PARTICULAR]:[PARTICULAR]],_xlfn.AGGREGATE(15,3,(Table1[[#This Row],[Details]:[Details]]=$B34)/(Table1[[#This Row],[Details]:[Details]]=$B34)*(ROW(Table1[[Details]:[Details]])-ROW(Table1[[#Headers],[Details]])),COLUMNS($C$10:CB33))),"")
B35: =IFERROR(INDEX(Table1[Details],MATCH(0,INDEX(COUNTIF($B$10:B34,Table1[Details]),),0)),"") -> 0 | C35: =IF(COLUMNS($C$10:C34)<=$A35,INDEX(Table1[[PARTICULAR]:[PARTICULAR]],_xlfn.AGGREGATE(15,3,(Table1[[#This Row],[Details]:[Details]]=$B35)/(Table1[[#This Row],[Details]:[Details]]=$B35)*(ROW(Table1[[Details]:[Details]])-ROW(Table1[[#Headers],[Details]])),COLUMNS($C$10:C34))),"") | D35: =IF(COLUMNS($C$10:D34)<=$A35,INDEX(Table1[[PARTICULAR]:[PARTICULAR]],_xlfn.AGGREGATE(15,3,(Table1[[#This Row],[Details]:[Details]]=$B35)/(Table1[[#This Row],[Details]:[Details]]=$B35)*(ROW(Table1[[Details]:[Details]])-ROW(Table1[[#Headers],[Details]])),COLUMNS($C$10:D34))),"") | E35: =IF(COLUMNS($C$10:E34)<=$A35,INDEX(Table1[[PARTICULAR]:[PARTICULAR]],_xlfn.AGGREGATE(15,3,(Table1[[#This Row],[Details]:[Details]]=$B35)/(Table1[[#This Row],[Details]:[Details]]=$B35)*(ROW(Table1[[Details]:[Details]])-ROW(Table1[[#Headers],[Details]])),COLUMNS($C$10:E34))),"") | F35: =IF(COLUMNS($C$10:F34)<=$A35,INDEX(Table1[[PARTICULAR]:[PARTICULAR]],_xlfn.AGGREGATE(15,3,(Table1[[#This Row],[Details]:[Details]]=$B35)/(Table1[[#This Row],[Details]:[Details]]=$B35)*(ROW(Table1[[Details]:[Details]])-ROW(Table1[[#Headers],[Details]])),COLUMNS($C$10:F34))),"") | G35: =IF(COLUMNS($C$10:G34)<=$A35,INDEX(Table1[[PARTICULAR]:[PARTICULAR]],_xlfn.AGGREGATE(15,3,(Table1[[#This Row],[Details]:[Details]]=$B35)/(Table1[[#This Row],[Details]:[Details]]=$B35)*(ROW(Table1[[Details]:[Details]])-ROW(Table1[[#Headers],[Details]])),COLUMNS($C$10:G34))),"") | H35: =IF(COLUMNS($C$10:H34)<=$A35,INDEX(Table1[[PARTICULAR]:[PARTICULAR]],_xlfn.AGGREGATE(15,3,(Table1[[#This Row],[Details]:[Details]]=$B35)/(Table1[[#This Row],[Details]:[Details]]=$B35)*(ROW(Table1[[Details]:[Details]])-ROW(Table1[[#Headers],[Details]])),COLUMNS($C$10:H34))),"") | I35: =IF(COLUMNS($C$10:I34)<=$A35,INDEX(Table1[[PARTICULAR]:[PARTICULAR]],_xlfn.AGGREGATE(15,3,(Table1[[#This Row],[Details]:[Details]]=$B35)/(Table1[[#This Row],[Details]:[Details]]=$B35)*(ROW(Table1[[Details]:[Details]])-ROW(Table1[[#Headers],[Details]])),COLUMNS($C$10:I34))),"") | J35: =IF(COLUMNS($C$10:J34)<=$A35,INDEX(Table1[[PARTICULAR]:[PARTICULAR]],_xlfn.AGGREGATE(15,3,(Table1[[#This Row],[Details]:[Details]]=$B35)/(Table1[[#This Row],[Details]:[Details]]=$B35)*(ROW(Table1[[Details]:[Details]])-ROW(Table1[[#Headers],[Details]])),COLUMNS($C$10:J34))),"") | ... CB35: =IF(COLUMNS($C$10:CB34)<=$A35,INDEX(Table1[[PARTICULAR]:[PARTICULAR]],_xlfn.AGGREGATE(15,3,(Table1[[#This Row],[Details]:[Details]]=$B35)/(Table1[[#This Row],[Details]:[Details]]=$B35)*(ROW(Table1[[Details]:[Details]])-ROW(Table1[[#Headers],[Details]])),COLUMNS($C$10:CB34))),"")
B36: =IFERROR(INDEX(Table1[Details],MATCH(0,INDEX(COUNTIF($B$10:B35,Table1[Details]),),0)),"") | C36: =IF(COLUMNS($C$10:C35)<=$A36,INDEX(Table1[[PARTICULAR]:[PARTICULAR]],_xlfn.AGGREGATE(15,3,(Table1[[#This Row],[Details]:[Details]]=$B36)/(Table1[[#This Row],[Details]:[Details]]=$B36)*(ROW(Table1[[Details]:[Details]])-ROW(Table1[[#Headers],[Details]])),COLUMNS($C$10:C35))),"") | D36: =IF(COLUMNS($C$10:D35)<=$A36,INDEX(Table1[[PARTICULAR]:[PARTICULAR]],_xlfn.AGGREGATE(15,3,(Table1[[#This Row],[Details]:[Details]]=$B36)/(Table1[[#This Row],[Details]:[Details]]=$B36)*(ROW(Table1[[Details]:[Details]])-ROW(Table1[[#Headers],[Details]])),COLUMNS($C$10:D35))),"") | E36: =IF(COLUMNS($C$10:E35)<=$A36,INDEX(Table1[[PARTICULAR]:[PARTICULAR]],_xlfn.AGGREGATE(15,3,(Table1[[#This Row],[Details]:[Details]]=$B36)/(Table1[[#This Row],[Details]:[Details]]=$B36)*(ROW(Table1[[Details]:[Details]])-ROW(Table1[[#Headers],[Details]])),COLUMNS($C$10:E35))),"") | F36: =IF(COLUMNS($C$10:F35)<=$A36,INDEX(Table1[[PARTICULAR]:[PARTICULAR]],_xlfn.AGGREGATE(15,3,(Table1[[#This Row],[Details]:[Details]]=$B36)/(Table1[[#This Row],[Details]:[Details]]=$B36)*(ROW(Table1[[Details]:[Details]])-ROW(Table1[[#Headers],[Details]])),COLUMNS($C$10:F35))),"") | G36: =IF(COLUMNS($C$10:G35)<=$A36,INDEX(Table1[[PARTICULAR]:[PARTICULAR]],_xlfn.AGGREGATE(15,3,(Table1[[#This Row],[Details]:[Details]]=$B36)/(Table1[[#This Row],[Details]:[Details]]=$B36)*(ROW(Table1[[Details]:[Details]])-ROW(Table1[[#Headers],[Details]])),COLUMNS($C$10:G35))),"") | H36: =IF(COLUMNS($C$10:H35)<=$A36,INDEX(Table1[[PARTICULAR]:[PARTICULAR]],_xlfn.AGGREGATE(15,3,(Table1[[#This Row],[Details]:[Details]]=$B36)/(Table1[[#This Row],[Details]:[Details]]=$B36)*(ROW(Table1[[Details]:[Details]])-ROW(Table1[[#Headers],[Details]])),COLUMNS($C$10:H35))),"") | I36: =IF(COLUMNS($C$10:I35)<=$A36,INDEX(Table1[[PARTICULAR]:[PARTICULAR]],_xlfn.AGGREGATE(15,3,(Table1[[#This Row],[Details]:[Details]]=$B36)/(Table1[[#This Row],[Details]:[Details]]=$B36)*(ROW(Table1[[Details]:[Details]])-ROW(Table1[[#Headers],[Details]])),COLUMNS($C$10:I35))),"") | J36: =IF(COLUMNS($C$10:J35)<=$A36,INDEX(Table1[[PARTICULAR]:[PARTICULAR]],_xlfn.AGGREGATE(15,3,(Table1[[#This Row],[Details]:[Details]]=$B36)/(Table1[[#This Row],[Details]:[Details]]=$B36)*(ROW(Table1[[Details]:[Details]])-ROW(Table1[[#Headers],[Details]])),COLUMNS($C$10:J35))),"") | ... CB36: =IF(COLUMNS($C$10:CB35)<=$A36,INDEX(Table1[[PARTICULAR]:[PARTICULAR]],_xlfn.AGGREGATE(15,3,(Table1[[#This Row],[Details]:[Details]]=$B36)/(Table1[[#This Row],[Details]:[Details]]=$B36)*(ROW(Table1[[Details]:[Details]])-ROW(Table1[[#Headers],[Details]])),COLUMNS($C$10:CB35))),"")
B37: =IFERROR(INDEX(Table1[Details],MATCH(0,INDEX(COUNTIF($B$10:B36,Table1[Details]),),0)),"") | C37: =IF(COLUMNS($C$10:C36)<=$A37,INDEX(Table1[[PARTICULAR]:[PARTICULAR]],_xlfn.AGGREGATE(15,3,(Table1[[#This Row],[Details]:[Details]]=$B37)/(Table1[[#This Row],[Details]:[Details]]=$B37)*(ROW(Table1[[Details]:[Details]])-ROW(Table1[[#Headers],[Details]])),COLUMNS($C$10:C36))),"") | D37: =IF(COLUMNS($C$10:D36)<=$A37,INDEX(Table1[[PARTICULAR]:[PARTICULAR]],_xlfn.AGGREGATE(15,3,(Table1[[#This Row],[Details]:[Details]]=$B37)/(Table1[[#This Row],[Details]:[Details]]=$B37)*(ROW(Table1[[Details]:[Details]])-ROW(Table1[[#Headers],[Details]])),COLUMNS($C$10:D36))),"") | E37: =IF(COLUMNS($C$10:E36)<=$A37,INDEX(Table1[[PARTICULAR]:[PARTICULAR]],_xlfn.AGGREGATE(15,3,(Table1[[#This Row],[Details]:[Details]]=$B37)/(Table1[[#This Row],[Details]:[Details]]=$B37)*(ROW(Table1[[Details]:[Details]])-ROW(Table1[[#Headers],[Details]])),COLUMNS($C$10:E36))),"") | F37: =IF(COLUMNS($C$10:F36)<=$A37,INDEX(Table1[[PARTICULAR]:[PARTICULAR]],_xlfn.AGGREGATE(15,3,(Table1[[#This Row],[Details]:[Details]]=$B37)/(Table1[[#This Row],[Details]:[Details]]=$B37)*(ROW(Table1[[Details]:[Details]])-ROW(Table1[[#Headers],[Details]])),COLUMNS($C$10:F36))),"") | G37: =IF(COLUMNS($C$10:G36)<=$A37,INDEX(Table1[[PARTICULAR]:[PARTICULAR]],_xlfn.AGGREGATE(15,3,(Table1[[#This Row],[Details]:[Details]]=$B37)/(Table1[[#This Row],[Details]:[Details]]=$B37)*(ROW(Table1[[Details]:[Details]])-ROW(Table1[[#Headers],[Details]])),COLUMNS($C$10:G36))),"") | H37: =IF(COLUMNS($C$10:H36)<=$A37,INDEX(Table1[[PARTICULAR]:[PARTICULAR]],_xlfn.AGGREGATE(15,3,(Table1[[#This Row],[Details]:[Details]]=$B37)/(Table1[[#This Row],[Details]:[Details]]=$B37)*(ROW(Table1[[Details]:[Details]])-ROW(Table1[[#Headers],[Details]])),COLUMNS($C$10:H36))),"") | I37: =IF(COLUMNS($C$10:I36)<=$A37,INDEX(Table1[[PARTICULAR]:[PARTICULAR]],_xlfn.AGGREGATE(15,3,(Table1[[#This Row],[Details]:[Details]]=$B37)/(Table1[[#This Row],[Details]:[Details]]=$B37)*(ROW(Table1[[Details]:[Details]])-ROW(Table1[[#Headers],[Details]])),COLUMNS($C$10:I36))),"") | J37: =IF(COLUMNS($C$10:J36)<=$A37,INDEX(Table1[[PARTICULAR]:[PARTICULAR]],_xlfn.AGGREGATE(15,3,(Table1[[#This Row],[Details]:[Details]]=$B37)/(Table1[[#This Row],[Details]:[Details]]=$B37)*(ROW(Table1[[Details]:[Details]])-ROW(Table1[[#Headers],[Details]])),COLUMNS($C$10:J36))),"") | ... CB37: =IF(COLUMNS($C$10:CB36)<=$A37,INDEX(Table1[[PARTICULAR]:[PARTICULAR]],_xlfn.AGGREGATE(15,3,(Table1[[#This Row],[Details]:[Details]]=$B37)/(Table1[[#This Row],[Details]:[Details]]=$B37)*(ROW(Table1[[Details]:[Details]])-ROW(Table1[[#Headers],[Details]])),COLUMNS($C$10:CB36))),"")
B38: =IFERROR(INDEX(Table1[Details],MATCH(0,INDEX(COUNTIF($B$10:B37,Table1[Details]),),0)),"")
B39: =IFERROR(INDEX(Table1[Details],MATCH(0,INDEX(COUNTIF($B$10:B38,Table1[Details]),),0)),"")
B40: =IFERROR(INDEX(Table1[Details],MATCH(0,INDEX(COUNTIF($B$10:B39,Table1[Details]),),0)),"")
B41: =IFERROR(INDEX(Table1[Details],MATCH(0,INDEX(COUNTIF($B$10:B40,Table1[Details]),),0)),"")
B42: =IFERROR(INDEX(Table1[Details],MATCH(0,INDEX(COUNTIF($B$10:B41,Table1[Details]),),0)),"")
B43: =IFERROR(INDEX(Table1[Details],MATCH(0,INDEX(COUNTIF($B$10:B42,Table1[Details]),),0)),"")
B44: =IFERROR(INDEX(Table1[Details],MATCH(0,INDEX(COUNTIF($B$10:B43,Table1[Details]),),0)),"")
B45: =IFERROR(INDEX(Table1[Details],MATCH(0,INDEX(COUNTIF($B$10:B44,Table1[Details]),),0)),"")
B46: =IFERROR(INDEX(Table1[Details],MATCH(0,INDEX(COUNTIF($B$10:B45,Table1[Details]),),0)),"")
B47: =IFERROR(INDEX(Table1[Details],MATCH(0,INDEX(COUNTIF($B$10:B46,Table1[Details]),),0)),"")
B48: =IFERROR(INDEX(Table1[Details],MATCH(0,INDEX(COUNTIF($B$10:B47,Table1[Details]),),0)),"")
B49: =IFERROR(INDEX(Table1[Details],MATCH(0,INDEX(COUNTIF($B$10:B48,Table1[Details]),),0)),"")
... B102: =IFERROR(INDEX(Table1[Details],MATCH(0,INDEX(COUNTIF($B$10:B101,Table1[Details]),),0)),"")

Sheet Auto PO
A1: Sr No. | B1: Doc. Type | C1: Vendor | D1: Purch.Org | E1: Purch.Group | F1: Site | G1: Short Text | H1: MC | I1: Item Cat | J1: Acct Assgt Cat | K1: GL Account | L1: Cost center | M1: Order Number | N1: Network | O1: Network Item | P1: Service No | Q1: Service Qty | R1: Net Price | S1: Tax Code | T1: Article No | U1: PO Qty | V1: PO Net Price | W1: Purchase Requistion | X1: Purchase Requistion Item | Y1: Campaign Code | Z1: Season | AA1: Campaign Name
A2: 1 | B2: ZVMC | C2: =+'PT ABC'!G$5 -> 7008750 | D2: 1000 | E2: 302 | F2: =+'PT ABC'!M$5 -> 0 | H2: OOTV2V12V | J2: F | K2: 417772 | M2: =F2&"VM2021" -> 0VM2021 | S2: V0 | T2: =+PIVOT!B5 -> 720001707 | U2: =+PIVOT!D5 -> Festive | V2: =+PIVOT!C5 -> 40 | Y2: =+PIVOT!A5 -> FE21/OCT/WINW | Z2: =+PIVOT!D5 -> Festive | AA2: =+PIVOT!E5 -> 0
A3: 1 | B3: ZVMC | C3: =+'PT ABC'!G$5 -> 7008750 | D3: 1000 | E3: 302 | F3: =+'PT ABC'!M$5 -> 0 | H3: OOTV2V12V | J3: F | K3: 417772 | M3: =F3&"VM2021" -> 0VM2021 | S3: V0 | T3: =+PIVOT!B6 -> 720001737 | U3: =+PIVOT!D6 -> Festive | V3: =+PIVOT!C6 -> 15 | Y3: =+PIVOT!A6 -> 0 | Z3: =+PIVOT!D6 -> Festive | AA3: =+PIVOT!E6 -> 0
A4: 1 | B4: ZVMC | C4: =+'PT ABC'!G$5 -> 7008750 | D4: 1000 | E4: 302 | F4: =+'PT ABC'!M$5 -> 0 | H4: OOTV2V12V | J4: F | K4: 417772 | M4: =F4&"VM2021" -> 0VM2021 | S4: V0 | T4: =+PIVOT!B7 -> 720001997 | U4: =+PIVOT!D7 -> Festive | V4: =+PIVOT!C7 -> 25 | Y4: =+PIVOT!A7 -> 0 | Z4: =+PIVOT!D7 -> Festive | AA4: =+PIVOT!E7 -> 0
A5: 1 | B5: ZVMC | C5: =+'PT ABC'!G$5 -> 7008750 | D5: 1000 | E5: 302 | F5: =+'PT ABC'!M$5 -> 0 | H5: OOTV2V12V | J5: F | K5: 417772 | M5: =F5&"VM2021" -> 0VM2021 | S5: V0 | T5: =+PIVOT!B8 -> 720002029 | U5: =+PIVOT!D8 -> Festive | V5: =+PIVOT!C8 -> 25 | Y5: =+PIVOT!A8 -> 0 | Z5: =+PIVOT!D8 -> Festive | AA5: =+PIVOT!E8 -> 0
A6: 1 | B6: ZVMC | C6: =+'PT ABC'!G$5 -> 7008750 | D6: 1000 | E6: 302 | F6: =+'PT ABC'!M$5 -> 0 | H6: OOTV2V12V | J6: F | K6: 417772 | M6: =F6&"VM2021" -> 0VM2021 | S6: V0 | T6: =+PIVOT!B9 -> 720002125 | U6: =+PIVOT!D9 -> Festive | V6: =+PIVOT!C9 -> 5 | Y6: =+PIVOT!A9 -> 0 | Z6: =+PIVOT!D9 -> Festive | AA6: =+PIVOT!E9 -> 0
A7: 1 | B7: ZVMC | C7: =+'PT ABC'!G$5 -> 7008750 | D7: 1000 | E7: 302 | F7: =+'PT ABC'!M$5 -> 0 | H7: OOTV2V12V | J7: F | K7: 417772 | M7: =F7&"VM2021" -> 0VM2021 | S7: V0 | T7: =+PIVOT!B10 -> 720002000 | U7: =+PIVOT!D10 -> Festive | V7: =+PIVOT!C10 -> 58 | Y7: =+PIVOT!A10 -> 0 | Z7: =+PIVOT!D10 -> Festive | AA7: =+PIVOT!E10 -> 0
A8: 1 | B8: ZVMC | C8: =+'PT ABC'!G$5 -> 7008750 | D8: 1000 | E8: 302 | F8: =+'PT ABC'!M$5 -> 0 | H8: OOTV2V12V | J8: F | K8: 417772 | M8: =F8&"VM2021" -> 0VM2021 | S8: V0 | T8: =+PIVOT!B11 -> 720001567 | U8: =+PIVOT!D11 -> Festive | V8: =+PIVOT!C11 -> 60 | Y8: =+PIVOT!A11 -> 0 | Z8: =+PIVOT!D11 -> Festive | AA8: =+PIVOT!E11 -> 0
A9: 1 | B9: ZVMC | C9: =+'PT ABC'!G$5 -> 7008750 | D9: 1000 | E9: 302 | F9: =+'PT ABC'!M$5 -> 0 | H9: OOTV2V12V | J9: F | K9: 417772 | M9: =F9&"VM2021" -> 0VM2021 | S9: V0 | T9: =+PIVOT!B12 -> 720001999 | U9: =+PIVOT!D12 -> Festive | V9: =+PIVOT!C12 -> 49 | Y9: =+PIVOT!A12 -> 0 | Z9: =+PIVOT!D12 -> Festive | AA9: =+PIVOT!E12 -> 0
A10: 1 | B10: ZVMC | C10: =+'PT ABC'!G$5 -> 7008750 | D10: 1000 | E10: 302 | F10: =+'PT ABC'!M$5 -> 0 | H10: OOTV2V12V | J10: F | K10: 417772 | M10: =F10&"VM2021" -> 0VM2021 | S10: V0 | T10: =+PIVOT!B13 -> 720002125 | U10: =+PIVOT!D13 -> Festive | V10: =+PIVOT!C13 -> 5 | Y10: =+PIVOT!A13 -> FE21/OCT/WIN | Z10: =+PIVOT!D13 -> Festive | AA10: =+PIVOT!E13 -> 0
A11: 1 | B11: ZVMC | C11: =+'PT ABC'!G$5 -> 7008750 | D11: 1000 | E11: 302 | F11: =+'PT ABC'!M$5 -> 0 | H11: OOTV2V12V | J11: F | K11: 417772 | M11: =F11&"VM2021" -> 0VM2021 | S11: V0 | T11: =+PIVOT!B14 -> 720001567 | U11: =+PIVOT!D14 -> Festive | V11: =+PIVOT!C14 -> 60 | Y11: =+PIVOT!A14 -> 0 | Z11: =+PIVOT!D14 -> Festive | AA11: =+PIVOT!E14 -> 0
A12: 1 | B12: ZVMC | C12: =+'PT ABC'!G$5 -> 7008750 | D12: 1000 | E12: 302 | F12: =+'PT ABC'!M$5 -> 0 | H12: OOTV2V12V | J12: F | K12: 417772 | M12: =F12&"VM2021" -> 0VM2021 | S12: V0 | T12: =+PIVOT!B15 -> 720002035 | U12: =+PIVOT!D15 -> Festive | V12: =+PIVOT!C15 -> (blank) | Y12: =+PIVOT!A15 -> 0 | Z12: =+PIVOT!D15 -> Festive | AA12: =+PIVOT!E15 -> 0
A13: 1 | B13: ZVMC | C13: =+'PT ABC'!G$5 -> 7008750 | D13: 1000 | E13: 302 | F13: =+'PT ABC'!M$5 -> 0 | H13: OOTV2V12V | J13: F | K13: 417772 | M13: =F13&"VM2021" -> 0VM2021 | S13: V0 | T13: =+PIVOT!B16 -> (blank) | U13: =+PIVOT!D16 -> Festive | V13: =+PIVOT!C16 -> (blank) | Y13: =+PIVOT!A16 -> 0 | Z13: =+PIVOT!D16 -> Festive | AA13: =+PIVOT!E16 -> 0
... A33: 1 | B33: ZVMC | C33: =+'PT ABC'!G$5 -> 7008750 | D33: 1000 | E33: 302 | F33: =+'PT ABC'!M$5 -> 0 | H33: OOTV2V12V | J33: F | K33: 417772 | M33: =F33&"VM2021" -> 0VM2021 | S33: V0 | T33: =+PIVOT!B36 -> 0 | U33: =+PIVOT!D36 -> 0 | V33: =+PIVOT!C36 -> 0 | Y33: =+PIVOT!A36 -> 0 | Z33: =+PIVOT!D36 -> 0 | AA33: =+PIVOT!E36 -> 0

Sheet PIVOT
E3: Values
A4: Campaign Code | B4: Article | C4: Rate | D4: Season | E4: Sum of Total SQFT | F4: Sum of Amount | G4: Sum of Total
A5: FE21/OCT/WINW | B5: 720001707 | C5: 40 | D5: Festive | E5: 0 | F5: 0 | G5: 0
B6: 720001737 | C6: 15 | D6: Festive | E6: 0 | F6: 0 | G6: 0
B7: 720001997 | C7: 25 | D7: Festive | E7: 0 | F7: 0 | G7: 0
B8: 720002029 | C8: 25 | D8: Festive | E8: 0 | F8: 0 | G8: 0
B9: 720002125 | C9: 5 | D9: Festive | E9: 0 | F9: 0 | G9: 0
B10: 720002000 | C10: 58 | D10: Festive | E10: 0 | F10: 0 | G10: 0
B11: 720001567 | C11: 60 | D11: Festive | E11: 0 | F11: 0 | G11: 0
B12: 720001999 | C12: 49 | D12: Festive | E12: 0 | F12: 0 | G12: 0
A13: FE21/OCT/WIN | B13: 720002125 | C13: 5 | D13: Festive | E13: 0 | F13: 0 | G13: 0
B14: 720001567 | C14: 60 | D14: Festive | E14: 0 | F14: 0 | G14: 0
B15: 720002035 | C15: (blank) | D15: Festive | E15: 0 | F15: 0 | G15: 0
B16: (blank) | C16: (blank) | D16: Festive
A17: Grand Total | E17: 0 | F17: 0 | G17: 0

Sheet Auto PO.
A1: Sr No. | B1: Doc. Type | C1: Vendor | D1: Purch.Org | E1: Purch.Group | F1: Site | G1: Short Text | H1: MC | I1: Item Cat | J1: Acct Assgt Cat | K1: GL Account | L1: Cost center | M1: Order Number | N1: Network | O1: Network Item | P1: Service No | Q1: Service Qty | R1: Net Price | S1: Tax Code | T1: Article No | U1: PO Qty | V1: PO Net Price | W1: Purchase Requistion | X1: Purchase Requistion Item | Y1: Campaign Code | Z1: Season | AA1: Campaign Name
A2: 1 | B2: ZVMC | C2: ='PT ABC'!$G$5 -> 7008750 | D2: 1000 | E2: 302 | F2: ='PT ABC'!$M$5 -> 0 | H2: OOTV2V12V | J2: F | K2: 417772 | M2: =F2&"VM2022" -> 0VM2022 | S2: V0 | T2: =Pivot.!D5 -> 720002030 | U2: =Pivot.!F5 -> 0 | V2: =Pivot.!E5 -> 40 | Y2: =Pivot.!A5 -> (blank) | Z2: =Pivot.!B5 -> (blank) | AA2: =Pivot.!C5 -> (blank)
A3: 1 | B3: ZVMC | C3: ='PT ABC'!$G$5 -> 7008750 | D3: 1000 | E3: 302 | F3: ='PT ABC'!$M$5 -> 0 | H3: OOTV2V12V | J3: F | K3: 417772 | M3: =F3&"VM2022" -> 0VM2022 | S3: V0 | T3: =Pivot.!D6 -> 0 | U3: =Pivot.!F6 -> 0 | V3: =Pivot.!E6 -> 0 | Y3: =Pivot.!A6 -> Grand Total | Z3: =Pivot.!B6 -> 0 | AA3: =Pivot.!C6 -> 0
A4: 1 | B4: ZVMC | C4: ='PT ABC'!$G$5 -> 7008750 | D4: 1000 | E4: 302 | F4: ='PT ABC'!$M$5 -> 0 | H4: OOTV2V12V | J4: F | K4: 417772 | M4: =F4&"VM2022" -> 0VM2022 | S4: V0 | T4: =Pivot.!D7 -> 0 | U4: =Pivot.!F7 -> 0 | V4: =Pivot.!E7 -> 0 | Y4: =Pivot.!A7 -> 0 | Z4: =Pivot.!B7 -> 0 | AA4: =Pivot.!C7 -> 0
A5: 1 | B5: ZVMC | C5: ='PT ABC'!$G$5 -> 7008750 | D5: 1000 | E5: 302 | F5: ='PT ABC'!$M$5 -> 0 | H5: OOTV2V12V | J5: F | K5: 417772 | M5: =F5&"VM2022" -> 0VM2022 | S5: V0 | T5: =Pivot.!D8 -> 0 | U5: =Pivot.!F8 -> 0 | V5: =Pivot.!E8 -> 0 | Y5: =Pivot.!A8 -> 0 | Z5: =Pivot.!B8 -> 0 | AA5: =Pivot.!C8 -> 0
A6: 1 | B6: ZVMC | C6: ='PT ABC'!$G$5 -> 7008750 | D6: 1000 | E6: 302 | F6: ='PT ABC'!$M$5 -> 0 | H6: OOTV2V12V | J6: F | K6: 417772 | M6: =F6&"VM2022" -> 0VM2022 | S6: V0 | T6: =Pivot.!D9 -> 0 | U6: =Pivot.!F9 -> 0 | V6: =Pivot.!E9 -> 0 | Y6: =Pivot.!A9 -> 0 | Z6: =Pivot.!B9 -> 0 | AA6: =Pivot.!C9 -> 0
A7: 1 | B7: ZVMC | C7: ='PT ABC'!$G$5 -> 7008750 | D7: 1000 | E7: 302 | F7: ='PT ABC'!$M$5 -> 0 | H7: OOTV2V12V | J7: F | K7: 417772 | M7: =F7&"VM2022" -> 0VM2022 | S7: V0 | T7: =Pivot.!D10 -> 0 | U7: =Pivot.!F10 -> 0 | V7: =Pivot.!E10 -> 0 | Y7: =Pivot.!A10 -> 0 | Z7: =Pivot.!B10 -> 0 | AA7: =Pivot.!C10 -> 0
A8: 1 | B8: ZVMC | C8: ='PT ABC'!$G$5 -> 7008750 | D8: 1000 | E8: 302 | F8: ='PT ABC'!$M$5 -> 0 | H8: OOTV2V12V | J8: F | K8: 417772 | M8: =F8&"VM2022" -> 0VM2022 | S8: V0 | T8: =Pivot.!D11 -> 0 | U8: =Pivot.!F11 -> 0 | V8: =Pivot.!E11 -> 0 | Y8: =Pivot.!A11 -> 0 | Z8: =Pivot.!B11 -> 0 | AA8: =Pivot.!C11 -> 0
A9: 1 | B9: ZVMC | C9: ='PT ABC'!$G$5 -> 7008750 | D9: 1000 | E9: 302 | F9: ='PT ABC'!$M$5 -> 0 | H9: OOTV2V12V | J9: F | K9: 417772 | M9: =F9&"VM2022" -> 0VM2022 | S9: V0 | T9: =Pivot.!D12 -> 0 | U9: =Pivot.!F12 -> 0 | V9: =Pivot.!E12 -> 0 | Y9: =Pivot.!A12 -> 0 | Z9: =Pivot.!B12 -> 0 | AA9: =Pivot.!C12 -> 0
